<?xml version="1.0" encoding="utf-8"?>
<!-- This URDF was automatically created by SolidWorks to URDF Exporter! Originally created by Stephen Brawner (brawner@gmail.com) 
     Commit Version: 1.5.1-0-g916b5db  Build Version: 1.5.7152.31018
     For more information, please see http://wiki.ros.org/sw_urdf_exporter -->
<robot
  name="robotti_9">
  <link
    name="base_link">
    <inertial>
      <origin
        xyz="-0.20109 0.00031558 0.073786"
        rpy="0 0 0" />
      <mass
        value="8.8662" />
      <inertia
        ixx="0.018873"
        ixy="7.9863E-06"
        ixz="-0.00013642"
        iyy="0.014385"
        iyz="7.753E-08"
        izz="0.025714" />
    </inertial>
    <visual>
      <origin
        xyz="0 0 0"
        rpy="0 0 0" />
      <geometry>
        <mesh
          filename="package://robotti_9/meshes/base_link.STL" />
      </geometry>
      <material
        name="">
        <color
          rgba="0.75294 0.75294 0.75294 1" />
      </material>
    </visual>
    <collision>
      <origin
        xyz="0 0 0"
        rpy="0 0 0" />
      <geometry>
        <mesh
          filename="package://robotti_9/meshes/base_hitbox.STL" />
      </geometry>
    </collision>
  </link>
  <link
    name="weapon_link">
    <inertial>
      <origin
        xyz="0 2.7756E-17 0"
        rpy="0 0 0" />
      <mass
        value="1.8773" />
      <inertia
        ixx="0.00053661"
        ixy="-1.3049E-18"
        ixz="1.4272E-14"
        iyy="0.016701"
        iyz="-1.0471E-19"
        izz="0.017183" />
    </inertial>
    <visual>
      <origin
        xyz="0 0 0"
        rpy="0 0 0" />
      <geometry>
        <mesh
          filename="package://robotti_9/meshes/weapon_link.STL" />
      </geometry>
      <material
        name="">
        <color
          rgba="0.64706 0.61961 0.58824 1" />
      </material>
    </visual>
    <collision>
      <origin
        xyz="0 0 0"
        rpy="0 0 0" />
      <geometry>
        <mesh
          filename="package://robotti_9/meshes/weapon_link.STL" />
      </geometry>
    </collision>
  </link>
  <joint
    name="weapon_joint"
    type="continuous">
    <origin
      xyz="-0.027 0.0002675 0.1072"
      rpy="0 0 0" />
    <parent
      link="base_link" />
    <child
      link="weapon_link" />
    <axis
      xyz="0 0 1" />
  </joint>
  <link
    name="l_wheel_link">
    <inertial>
      <origin
        xyz="3.6082E-16 -0.012645 -2.8866E-15"
        rpy="0 0 0" />
      <mass
        value="0.46812" />
      <inertia
        ixx="0.0009439"
        ixy="-1.0482E-17"
        ixz="4.0042E-18"
        iyy="0.0018198"
        iyz="-5.2295E-18"
        izz="0.0009439" />
    </inertial>
    <visual>
      <origin
        xyz="0 0 0"
        rpy="0 0 0" />
      <geometry>
        <mesh
          filename="package://robotti_9/meshes/l_wheel_link.STL" />
      </geometry>
      <material
        name="">
        <color
          rgba="0.29804 0.29804 0.29804 1" />
      </material>
    </visual>
    <collision>
      <origin
        xyz="0 0 0"
        rpy="0 0 0" />
      <geometry>
        <mesh
          filename="package://robotti_9/meshes/l_wheel_link.STL" />
      </geometry>
    </collision>
  </link>
  <joint
    name="l_wheel_joint"
    type="continuous">
    <origin
      xyz="-0.276 0.15027 0.076995"
      rpy="0 0 0" />
    <parent
      link="base_link" />
    <child
      link="l_wheel_link" />
    <axis
      xyz="0 1 0" />
  </joint>
  <link
    name="r_wheel_link">
    <inertial>
      <origin
        xyz="3.3307E-16 0.012645 2.7409E-15"
        rpy="0 0 0" />
      <mass
        value="0.46812" />
      <inertia
        ixx="0.0009439"
        ixy="1.046E-17"
        ixz="-4.1427E-18"
        iyy="0.0018198"
        iyz="-1.2713E-17"
        izz="0.0009439" />
    </inertial>
    <visual>
      <origin
        xyz="0 0 0"
        rpy="0 0 0" />
      <geometry>
        <mesh
          filename="package://robotti_9/meshes/r_wheel_link.STL" />
      </geometry>
      <material
        name="">
        <color
          rgba="0.29804 0.29804 0.29804 1" />
      </material>
    </visual>
    <collision>
      <origin
        xyz="0 0 0"
        rpy="0 0 0" />
      <geometry>
        <mesh
          filename="package://robotti_9/meshes/r_wheel_link.STL" />
      </geometry>
    </collision>
  </link>
  <joint
    name="r_wheel_joint"
    type="continuous">
    <origin
      xyz="-0.276 -0.14973 0.076995"
      rpy="0 0 0" />
    <parent
      link="base_link" />
    <child
      link="r_wheel_link" />
    <axis
      xyz="0 1 0" />
  </joint>
</robot>