<?xml version="1.0" encoding="utf-8"?>
<!-- This URDF was automatically created by SolidWorks to URDF Exporter! Originally created by Stephen Brawner (brawner@gmail.com) 
     Commit Version: 1.5.1-0-g916b5db  Build Version: 1.5.7152.31018
     For more information, please see http://wiki.ros.org/sw_urdf_exporter -->
<robot
  name="robotti_7">
  <link
    name="base_link">
    <inertial>
      <origin
        xyz="-0.15157 -0.0015068 0.082359"
        rpy="0 0 0" />
      <mass
        value="9.9872" />
      <inertia
        ixx="0.031957"
        ixy="8.2128E-07"
        ixz="-0.00025479"
        iyy="0.051797"
        iyz="-3.0837E-07"
        izz="0.074737" />
    </inertial>
    <visual>
      <origin
        xyz="0 0 0"
        rpy="0 0 0" />
      <geometry>
        <mesh
          filename="package://robotti_7/meshes/base_link.STL" />
      </geometry>
      <material
        name="">
        <color
          rgba="0.75294 0.75294 0.75294 1" />
      </material>
    </visual>
    <collision>
      <origin
        xyz="0 0 0"
        rpy="0 0 0" />
      <geometry>
        <mesh
          filename="package://robotti_7/meshes/base_hitbox.STL" />
      </geometry>
    </collision>
  </link>
  <link
    name="r_wheel_link">
    <inertial>
      <origin
        xyz="-1.3878E-17 -2.7756E-17 0"
        rpy="0 0 0" />
      <mass
        value="0.57875" />
      <inertia
        ixx="0.0012863"
        ixy="-1.2187E-19"
        ixz="-4.5987E-19"
        iyy="0.0024817"
        iyz="-1.4717E-21"
        izz="0.0012863" />
    </inertial>
    <visual>
      <origin
        xyz="0 0 0"
        rpy="0 0 0" />
      <geometry>
        <mesh
          filename="package://robotti_7/meshes/r_wheel_link.STL" />
      </geometry>
      <material
        name="">
        <color
          rgba="0.75294 0.75294 0.75294 1" />
      </material>
    </visual>
    <collision>
      <origin
        xyz="0 0 0"
        rpy="0 0 0" />
      <geometry>
        <mesh
          filename="package://robotti_7/meshes/r_wheel_link.STL" />
      </geometry>
    </collision>
  </link>
  <joint
    name="r_wheel_joint"
    type="continuous">
    <origin
      xyz="-0.26785 -0.16 0.0877"
      rpy="0 0 0" />
    <parent
      link="base_link" />
    <child
      link="r_wheel_link" />
    <axis
      xyz="0 1 0" />
  </joint>
  <link
    name="l_wheel_link">
    <inertial>
      <origin
        xyz="1.3878E-17 0 -1.3878E-17"
        rpy="0 0 0" />
      <mass
        value="0.57875" />
      <inertia
        ixx="0.0012863"
        ixy="2.1004E-19"
        ixz="4.4327E-19"
        iyy="0.0024817"
        iyz="5.784E-20"
        izz="0.0012863" />
    </inertial>
    <visual>
      <origin
        xyz="0 0 0"
        rpy="0 0 0" />
      <geometry>
        <mesh
          filename="package://robotti_7/meshes/l_wheel_link.STL" />
      </geometry>
      <material
        name="">
        <color
          rgba="0.75294 0.75294 0.75294 1" />
      </material>
    </visual>
    <collision>
      <origin
        xyz="0 0 0"
        rpy="0 0 0" />
      <geometry>
        <mesh
          filename="package://robotti_7/meshes/l_wheel_link.STL" />
      </geometry>
    </collision>
  </link>
  <joint
    name="l_wheel_joint"
    type="continuous">
    <origin
      xyz="-0.26785 0.16 0.0877"
      rpy="0 0 0" />
    <parent
      link="base_link" />
    <child
      link="l_wheel_link" />
    <axis
      xyz="0 1 0" />
  </joint>
  <link
    name="weapon_link">
    <inertial>
      <origin
        xyz="8.3267E-17 -9.1012E-17 0.0022845"
        rpy="0 0 0" />
      <mass
        value="0.36276" />
      <inertia
        ixx="0.0046726"
        ixy="6.4429E-13"
        ixz="-2.2024E-20"
        iyy="2.2265E-05"
        iyz="6.5138E-19"
        izz="0.0046934" />
    </inertial>
    <visual>
      <origin
        xyz="0 0 0"
        rpy="0 0 0" />
      <geometry>
        <mesh
          filename="package://robotti_7/meshes/weapon_link.STL" />
      </geometry>
      <material
        name="">
        <color
          rgba="0.65098 0.61961 0.58824 1" />
      </material>
    </visual>
    <collision>
      <origin
        xyz="0 0 0"
        rpy="0 0 0" />
      <geometry>
        <mesh
          filename="package://robotti_7/meshes/weapon_link.STL" />
      </geometry>
    </collision>
  </link>
  <joint
    name="weapon_joint"
    type="continuous">
    <origin
      xyz="0 0 0.005"
      rpy="0 0 0" />
    <parent
      link="base_link" />
    <child
      link="weapon_link" />
    <axis
      xyz="0 0 -1" />
  </joint>
</robot>