<?xml version="1.0" encoding="utf-8"?>
<!-- This URDF was automatically created by SolidWorks to URDF Exporter! Originally created by Stephen Brawner (brawner@gmail.com) 
     Commit Version: 1.5.1-0-g916b5db  Build Version: 1.5.7152.31018
     For more information, please see http://wiki.ros.org/sw_urdf_exporter -->
<robot
  name="robotti_8">
  <link
    name="base_link">
    <inertial>
      <origin
        xyz="-0.1748 -0.0015373 0.13638"
        rpy="0 0 0" />
      <mass
        value="6.5896" />
      <inertia
        ixx="0.013808"
        ixy="0.00028037"
        ixz="2.1258E-08"
        iyy="0.016936"
        iyz="-5.3795E-08"
        izz="0.026797" />
    </inertial>
    <visual>
      <origin
        xyz="0 0 0"
        rpy="0 0 0" />
      <geometry>
        <mesh
          filename="package://robotti_8/meshes/base_link.STL" />
      </geometry>
      <material
        name="">
        <color
          rgba="0.75294 0.75294 0.75294 1" />
      </material>
    </visual>
    <collision>
      <origin
        xyz="0 0 0"
        rpy="0 0 0" />
      <geometry>
        <mesh
          filename="package://robotti_8/meshes/base_hitbox.STL" />
      </geometry>
    </collision>
  </link>
  <link
    name="r_wheel_link">
    <inertial>
      <origin
        xyz="-9.9869E-10 -0.01875 -8.3389E-12"
        rpy="0 0 0" />
      <mass
        value="0.39239" />
      <inertia
        ixx="0.00044476"
        ixy="-1.5893E-14"
        ixz="1.817E-13"
        iyy="0.00079969"
        iyz="-2.6126E-13"
        izz="0.00044476" />
    </inertial>
    <visual>
      <origin
        xyz="0 0 0"
        rpy="0 0 0" />
      <geometry>
        <mesh
          filename="package://robotti_8/meshes/r_wheel_link.STL" />
      </geometry>
      <material
        name="">
        <color
          rgba="1 1 1 1" />
      </material>
    </visual>
    <collision>
      <origin
        xyz="0 0 0"
        rpy="0 0 0" />
      <geometry>
        <mesh
          filename="package://robotti_8/meshes/r_wheel_link.STL" />
      </geometry>
    </collision>
  </link>
  <joint
    name="r_wheel_joint"
    type="continuous">
    <origin
      xyz="-0.35891 -0.17621 0.14358"
      rpy="0 0 0" />
    <parent
      link="base_link" />
    <child
      link="r_wheel_link" />
    <axis
      xyz="0 -1 0" />
  </joint>
  <link
    name="l_wheel_link">
    <inertial>
      <origin
        xyz="-9.3811E-10 0.01875 -2.7156E-11"
        rpy="0 0 0" />
      <mass
        value="0.39239" />
      <inertia
        ixx="0.00044476"
        ixy="6.7332E-15"
        ixz="1.9888E-13"
        iyy="0.00079969"
        iyz="-1.8841E-13"
        izz="0.00044476" />
    </inertial>
    <visual>
      <origin
        xyz="0 0 0"
        rpy="0 0 0" />
      <geometry>
        <mesh
          filename="package://robotti_8/meshes/l_wheel_link.STL" />
      </geometry>
      <material
        name="">
        <color
          rgba="1 1 1 1" />
      </material>
    </visual>
    <collision>
      <origin
        xyz="0 0 0"
        rpy="0 0 0" />
      <geometry>
        <mesh
          filename="package://robotti_8/meshes/l_wheel_link.STL" />
      </geometry>
    </collision>
  </link>
  <joint
    name="l_wheel_joint"
    type="continuous">
    <origin
      xyz="-0.35891 0.16621 0.14358"
      rpy="0 0 0" />
    <parent
      link="base_link" />
    <child
      link="l_wheel_link" />
    <axis
      xyz="0 -1 0" />
  </joint>
  <link
    name="weapon_link">
    <inertial>
      <origin
        xyz="-5.5511E-17 -0.002 -1.9949E-17"
        rpy="0 0 0" />
      <mass
        value="1.2336" />
      <inertia
        ixx="0.0039975"
        ixy="-1.7007E-20"
        ixz="-5.4842E-20"
        iyy="0.0079916"
        iyz="7.323E-21"
        izz="0.0039975" />
    </inertial>
    <visual>
      <origin
        xyz="0 0 0"
        rpy="0 0 0" />
      <geometry>
        <mesh
          filename="package://robotti_8/meshes/weapon_link.STL" />
      </geometry>
      <material
        name="">
        <color
          rgba="0.89804 0.89804 0.89804 1" />
      </material>
    </visual>
    <collision>
      <origin
        xyz="0 0 0"
        rpy="0 0 0" />
      <geometry>
        <mesh
          filename="package://robotti_8/meshes/weapon_hitbox.STL" />
      </geometry>
    </collision>
  </link>
  <joint
    name="weapon_joint"
    type="continuous">
    <origin
      xyz="-0.033983 -0.0093 0.13862"
      rpy="0 0 0" />
    <parent
      link="base_link" />
    <child
      link="weapon_link" />
    <axis
      xyz="0 -1 0" />
  </joint>
</robot>