<?xml version="1.0" encoding="utf-8"?>
<!-- This URDF was automatically created by SolidWorks to URDF Exporter! Originally created by Stephen Brawner (brawner@gmail.com) 
     Commit Version: 1.6.0-1-g15f4949  Build Version: 1.6.7594.29634
     For more information, please see http://wiki.ros.org/sw_urdf_exporter -->
<robot
  name="r6_2020">
  <link
    name="base_link">
    <inertial>
      <origin
        xyz="0.034059 -8.9497E-07 0.10131"
        rpy="0 0 0" />
      <mass
        value="10.069" />
      <inertia
        ixx="0.11625"
        ixy="-4.5578E-07"
        ixz="0.011207"
        iyy="0.055121"
        iyz="-1.3817E-07"
        izz="0.13265" />
    </inertial>
    <visual>
      <origin
        xyz="0 0 0"
        rpy="0 0 0" />
      <geometry>
        <mesh
          filename="package://r6_2020/meshes/base_link.STL" />
      </geometry>
      <material
        name="">
        <color
          rgba="0.89804 0.91765 0.92941 1" />
      </material>
    </visual>
    <collision>
      <origin
        xyz="0 0 0"
        rpy="0 0 0" />
      <geometry>
        <mesh
          filename="package://r6_2020/meshes/base_link.STL" />
      </geometry>
    </collision>
  </link>
  <link
    name="wheel_left_link">
    <inertial>
      <origin
        xyz="0.01854 0.19833 0.07"
        rpy="0 0 0" />
      <mass
        value="0.18293" />
      <inertia
        ixx="0.00023794"
        ixy="1.5004E-19"
        ixz="-2.268E-21"
        iyy="0.00047128"
        iyz="1.6075E-19"
        izz="0.00023794" />
    </inertial>
    <visual>
      <origin
        xyz="0 0 0"
        rpy="0 0 0" />
      <geometry>
        <mesh
          filename="package://r6_2020/meshes/wheel_left_link.STL" />
      </geometry>
      <material
        name="">
        <color
          rgba="0.79216 0.81961 0.93333 1" />
      </material>
    </visual>
    <collision>
      <origin
        xyz="0 0 0"
        rpy="0 0 0" />
      <geometry>
        <mesh
          filename="package://r6_2020/meshes/wheel_left_link.STL" />
      </geometry>
    </collision>
  </link>
  <joint
    name="wheel_left_joint"
    type="continuous">
    <origin
      xyz="0 0 0"
      rpy="0 0 0" />
    <parent
      link="base_link" />
    <child
      link="wheel_left_link" />
    <axis
      xyz="0 1 0" />
  </joint>
  <link
    name="wheel_right_link">
    <inertial>
      <origin
        xyz="0.01846 -0.19833 0.07"
        rpy="0 0 0" />
      <mass
        value="0.18293" />
      <inertia
        ixx="0.00023794"
        ixy="-1.6976E-19"
        ixz="-9.549E-21"
        iyy="0.00047128"
        iyz="-2.3063E-19"
        izz="0.00023794" />
    </inertial>
    <visual>
      <origin
        xyz="0 0 0"
        rpy="0 0 0" />
      <geometry>
        <mesh
          filename="package://r6_2020/meshes/wheel_right_link.STL" />
      </geometry>
      <material
        name="">
        <color
          rgba="0.79216 0.81961 0.93333 1" />
      </material>
    </visual>
    <collision>
      <origin
        xyz="0 0 0"
        rpy="0 0 0" />
      <geometry>
        <mesh
          filename="package://r6_2020/meshes/wheel_right_link.STL" />
      </geometry>
    </collision>
  </link>
  <joint
    name="wheel_right_joint"
    type="continuous">
    <origin
      xyz="0 0 0"
      rpy="0 0 0" />
    <parent
      link="base_link" />
    <child
      link="wheel_right_link" />
    <axis
      xyz="0 1 0" />
  </joint>
  <link
    name="weapon_link">
    <inertial>
      <origin
        xyz="0.15788 0.0001548 0.14826"
        rpy="0 0 0" />
      <mass
        value="1.2786" />
      <inertia
        ixx="0.0043475"
        ixy="3.8002E-18"
        ixz="-1.1018E-18"
        iyy="0.0043475"
        iyz="-4.8347E-20"
        izz="0.0086897" />
    </inertial>
    <visual>
      <origin
        xyz="0 0 0"
        rpy="0 0 0" />
      <geometry>
        <mesh
          filename="package://r6_2020/meshes/weapon_link.STL" />
      </geometry>
      <material
        name="">
        <color
          rgba="0.77647 0.75686 0.73725 1" />
      </material>
    </visual>
    <collision>
      <origin
        xyz="0 0 0"
        rpy="0 0 0" />
      <geometry>
        <mesh
          filename="package://r6_2020/meshes/weapon_link.STL" />
      </geometry>
    </collision>
  </link>
  <joint
    name="weapon_joint"
    type="continuous">
    <origin
      xyz="0 0 0"
      rpy="0 0 0" />
    <parent
      link="base_link" />
    <child
      link="weapon_link" />
    <axis
      xyz="0 0 -1" />
  </joint>
</robot>