<?xml version="1.0" encoding="utf-8"?>
<!-- This URDF was automatically created by SolidWorks to URDF Exporter! Originally created by Stephen Brawner (brawner@gmail.com) 
     Commit Version: 1.6.0-1-g15f4949  Build Version: 1.6.7594.29634
     For more information, please see http://wiki.ros.org/sw_urdf_exporter -->
<robot
  name="r8_2020">
  <link
    name="base_link">
    <inertial>
      <origin
        xyz="0.024609 1.3198E-05 0.083981"
        rpy="0 0 0" />
      <mass
        value="8.9635" />
      <inertia
        ixx="0.049118"
        ixy="-3.0819E-05"
        ixz="0.00014761"
        iyy="0.014351"
        iyz="4.0842E-08"
        izz="0.057037" />
    </inertial>
    <visual>
      <origin
        xyz="0 0 0"
        rpy="0 0 0" />
      <geometry>
        <mesh
          filename="package://r8_2020/meshes/base_link.STL" />
      </geometry>
      <material
        name="">
        <color
          rgba="0.75294 0.75294 0.75294 1" />
      </material>
    </visual>
    <collision>
      <origin
        xyz="0 0 0"
        rpy="0 0 0" />
      <geometry>
        <mesh
          filename="package://r8_2020/meshes/base_link.STL" />
      </geometry>
    </collision>
  </link>
  <link
    name="left_wheel_link">
    <inertial>
      <origin
        xyz="0 -0.00085238 0"
        rpy="0 0 0" />
      <mass
        value="0.23727" />
      <inertia
        ixx="0.00040071"
        ixy="8.7944E-20"
        ixz="-1.2664E-21"
        iyy="0.00079555"
        iyz="-1.466E-20"
        izz="0.00040071" />
    </inertial>
    <visual>
      <origin
        xyz="0 0 0"
        rpy="0 0 0" />
      <geometry>
        <mesh
          filename="package://r8_2020/meshes/left_wheel_link.STL" />
      </geometry>
      <material
        name="">
        <color
          rgba="0.79216 0.81961 0.93333 1" />
      </material>
    </visual>
    <collision>
      <origin
        xyz="0 0 0"
        rpy="0 0 0" />
      <geometry>
        <mesh
          filename="package://r8_2020/meshes/left_wheel_link.STL" />
      </geometry>
    </collision>
  </link>
  <joint
    name="left_wheel_joint"
    type="continuous">
    <origin
      xyz="0 0.18883 0.088"
      rpy="0 0 0" />
    <parent
      link="base_link" />
    <child
      link="left_wheel_link" />
    <axis
      xyz="0 1 0" />
  </joint>
  <link
    name="right_wheel_link">
    <inertial>
      <origin
        xyz="0 0.00085238 0"
        rpy="0 0 0" />
      <mass
        value="0.23727" />
      <inertia
        ixx="0.00040071"
        ixy="-2.6705E-18"
        ixz="1.0519E-20"
        iyy="0.00079555"
        iyz="1.4331E-20"
        izz="0.00040071" />
    </inertial>
    <visual>
      <origin
        xyz="0 0 0"
        rpy="0 0 0" />
      <geometry>
        <mesh
          filename="package://r8_2020/meshes/right_wheel_link.STL" />
      </geometry>
      <material
        name="">
        <color
          rgba="0.79216 0.81961 0.93333 1" />
      </material>
    </visual>
    <collision>
      <origin
        xyz="0 0 0"
        rpy="0 0 0" />
      <geometry>
        <mesh
          filename="package://r8_2020/meshes/right_wheel_link.STL" />
      </geometry>
    </collision>
  </link>
  <joint
    name="right_wheel_joint"
    type="continuous">
    <origin
      xyz="0 -0.18883 0.088"
      rpy="0 0 0" />
    <parent
      link="base_link" />
    <child
      link="right_wheel_link" />
    <axis
      xyz="0 1 0" />
  </joint>
  <link
    name="weapon_link">
    <inertial>
      <origin
        xyz="-7.7716E-16 -2.7756E-16 0"
        rpy="0 0 0" />
      <mass
        value="0.28203" />
      <inertia
        ixx="0.0010095"
        ixy="-1.5935E-18"
        ixz="-1.67E-20"
        iyy="0.0010095"
        iyz="3.1708E-18"
        izz="0.0020186" />
    </inertial>
    <visual>
      <origin
        xyz="0 0 0"
        rpy="0 0 0" />
      <geometry>
        <mesh
          filename="package://r8_2020/meshes/weapon_link.STL" />
      </geometry>
      <material
        name="">
        <color
          rgba="0.89804 0.91765 0.92941 1" />
      </material>
    </visual>
    <collision>
      <origin
        xyz="0 0 0"
        rpy="0 0 0" />
      <geometry>
        <mesh
          filename="package://r8_2020/meshes/weapon_link.STL" />
      </geometry>
    </collision>
  </link>
  <joint
    name="weapon_joint"
    type="continuous">
    <origin
      xyz="0.13388 -0.0001548 0.0438"
      rpy="0 0 0" />
    <parent
      link="base_link" />
    <child
      link="weapon_link" />
    <axis
      xyz="0 0 -1" />
  </joint>
  <link
    name="rplidar_link">
    <inertial>
      <origin
        xyz="-0.044908 0.0066147 0.16457"
        rpy="0 0 0" />
      <mass
        value="1.3308" />
      <inertia
        ixx="0.0009607"
        ixy="8.0198E-07"
        ixz="3.0916E-06"
        iyy="0.00061492"
        iyz="0.00015824"
        izz="0.0010982" />
    </inertial>
    <visual>
      <origin
        xyz="0 0 0"
        rpy="0 0 0" />
      <geometry>
        <mesh
          filename="package://r8_2020/meshes/rplidar_link.STL" />
      </geometry>
      <material
        name="">
        <color
          rgba="0.79216 0.81961 0.93333 1" />
      </material>
    </visual>
    <collision>
      <origin
        xyz="0 0 0"
        rpy="0 0 0" />
      <geometry>
        <mesh
          filename="package://r8_2020/meshes/rplidar_link.STL" />
      </geometry>
    </collision>
  </link>
  <joint
    name="rplidar_joint"
    type="fixed">
    <origin
      xyz="0 0 0"
      rpy="0 0 0" />
    <parent
      link="base_link" />
    <child
      link="rplidar_link" />
    <axis
      xyz="0 0 0" />
  </joint>
</robot>